Workbook

Sheet AACOMM
A1: 제공항목
A2: 한글필드명 | B2: 필드명 | D2: ※ n-kesa 환경에서 CA 영역 항목은 M/F 과 상이함
A3: 고객식별자 | B3: AACOM-CUST-IDNFR | D3: - 코어현대화 고객 CA 영역에서의 제공항목은 고객기본정보의 항목입니다
A4: 고객관리번호 | B4: AACOM-CUST-MGT-NO
A5: 고객고유번호 | B5: AACOM-CUNIQNO
A6: 고객고유번호구분코드 | B6: AACOM-CUNIQNO-DSTCD
A7: 고객명1 | B7: AACOM-DTALS-CUSTNM1
A8: 고객명2 | B8: AACOM-DTALS-CUSTNM2
A9: 고객유형분류구분코드 | B9: AACOM-CUST-PZ-CLSFI-DSTCD
A10: 세부고객유형분류구분코드 | B10: AACOM-DTALS-CPC-DSTCD
A11: 거래자구분코드 | B11: AACOM-TRANR-DSTCD
A12: 잠재고객여부 | B12: AACOM-POTEN-CUST-YN
A13: 고객상태구분코드 | B13: AACOM-CUST-STUS-DSTCD
A14: 최고등급구분코드 | B14: AACOM-HGST-CUST-DSTCD
A15: 알리미표시여부 | B15: AACOM-ALMI-REPSNT-YN
... A32: 기타대체번호 | B32: AACOM-ALTR-NO

Sheet 미제공항목
A1: 미제공항목 | D1: TOBE 사용 방법
A2: 한글필드명 | B2: 필드명 | D2: 호출모듈 | E2: 항목 | F2: 비고
A3: 폼ID | B3: AACOM-FM-ID | D3: N/A | H3: ※ 고객 컨플 가이드 참조
A4: 카드등급구분코드1 | B4: AACOM-CARD-GRD-DSTCD1 | D4: N/A | H4: 3.0.5 고객정보모듈 매핑 및 사용자가이드 - 코어뱅킹현대화1단계 - KB Confluence Data Center
A5: 카드등급구분코드2 | B5: AACOM-CARD-GRD-DSTCD2 | D5: N/A
A6: 카드등급구분코드3 | B6: AACOM-CARD-GRD-DSTCD3 | D6: N/A
A7: 금지정보구분코드01 | B7: AACOM-EMBG-I-DSTIC-CD01 | D7: N/A
A8: 금지정보구분코드02 | B8: AACOM-EMBG-I-DSTIC-CD02 | D8: N/A
A9: 금지정보구분코드03 | B9: AACOM-EMBG-I-DSTIC-CD03 | D9: N/A
A10: 금지정보구분코드04 | B10: AACOM-EMBG-I-DSTIC-CD04 | D10: N/A
A11: 금지정보구분코드05 | B11: AACOM-EMBG-I-DSTIC-CD05 | D11: N/A
A12: 금지정보구분코드06 | B12: AACOM-EMBG-I-DSTIC-CD06 | D12: N/A
A13: 금지정보구분코드07 | B13: AACOM-EMBG-I-DSTIC-CD07 | D13: N/A
A14: 금지정보구분코드08 | B14: AACOM-EMBG-I-DSTIC-CD08 | D14: N/A
A15: 금지정보구분코드09 | B15: AACOM-EMBG-I-DSTIC-CD | D15: N/A
A16: 금지정보구분코드10 | B16: AACOM-EMBG-I-DSTIC-CD10 | D16: N/A
A17: 정상부가메시지코드 | B17: AACOM-ADED-MSG-CD | D17: N/A
A18: 알리미표시여부 | B18: AACOM-ALMI-REPSNT-YN
A19: 기업규모구분코드 | B19: AACOM-CORP-SCAL-DSTCD | D19: FUBznoInfoMgt.getCoprCustDtailInfo() | E19: outCorpScalDstcd | F19: coprInfo 그룹 내 필드
A20: 표준산업분류코드 | B20: AACOM-STND-I-CLSFI-CD | D20: FUBznoInfoMgt.getCoprCustDtailInfo() | E20: outStndIdstryClsfiCd | F20: coprInfo 그룹 내 필드
A21: 개인사업자공동대표여부 | B21: AACOM-PPSN-B-JNT-RPSNT-YN | D21: N/A
A22: 등급안내거절여부 | B22: AACOM-GRD-GUID-REJCN-YN | D22: N/A
A23: 국적국가코드 | B23: AACOM-NATLTY-NATNL-CD | F23: 필요시 문의요청
A24: 거주소재지국가코드 | B24: AACOM-RESI-LOC-NATNL-CD | F24: 필요시 문의요청
A25: 마케팅활용동의구분코드 | B25: AACOM-MAKTNG-PC-DSTCD | D25: FUPpsnInfoMgt.getCustMaktngInfo() | E25: outMaktngPuseCnsntDstcd
A26: 카드고객명 | B26: AACOM-CARD-CUSTNM | D26: N/A
A27: 카드이용가능여부 | B27: AACOM-CARD-U-ABIL-DSTCD | D27: N/A
A28: 종료조회권한부여여부 | B28: AACOM-END-I-ATH-GRNT-YN | D28: N/A
A29: 종료조회에러여부 | B29: AACOM-END-INQURY-ERR-YN | D29: N/A
A30: 알리미대상구분 | B30: AACOM-ALMI-TAGET-DSTCD | D30: N/A
A31: 고객영역예비 | B31: AACOM-SPARE | D31: N/A

Sheet MF-AACOM
A1: 한글필드명 | B1: 타입 | C1: 옵셋 | D1: 길이 | E1: 소수 | F1: 값 | G1: 필드명 | H1: 후처리
A2: 고객식별자 | B2: X | C2: 3701 | D2: 10 | E2: 0 | F2: 1241745286 | G2: AACOM-CUST-IDNFR | H2: O | I2: =VLOOKUP(G2,미제공항목!$B$3:$B$43,1,FALSE) -> #N/A
A3: 고객관리번호 | B3: X | C3: 3711 | D3: 5 | E3: 0 | F3: 00000 | G3: AACOM-CUST-MGT-NO | H3: O | I3: =VLOOKUP(G3,미제공항목!$B$3:$B$43,1,FALSE) -> #N/A
A4: 고객고유번호 | B4: X | C4: 3716 | D4: 20 | E4: 0 | F4: 811226******* | G4: AACOM-CUNIQNO | H4: O | I4: =VLOOKUP(G4,미제공항목!$B$3:$B$43,1,FALSE) -> #N/A
A5: 고객고유번호구분코드 | B5: X | C5: 3736 | D5: 2 | E5: 0 | F5: 01 | G5: AACOM-CUNIQNO-DSTCD | H5: O | I5: =VLOOKUP(G5,미제공항목!$B$3:$B$43,1,FALSE) -> #N/A
A6: 고객명1 | B6: X | C6: 3738 | D6: 52 | E6: 0 | F6: 차지종 | G6: AACOM-DTALS-CUSTNM1 | I6: =VLOOKUP(G6,미제공항목!$B$3:$B$43,1,FALSE) -> #N/A
A7: 고객명2 | B7: X | C7: 3790 | D7: 52 | E7: 0 | F7: 차지종 | G7: AACOM-DTALS-CUSTNM2 | H7: O | I7: =VLOOKUP(G7,미제공항목!$B$3:$B$43,1,FALSE) -> #N/A
A8: 고객유형분류구분코드 | B8: X | C8: 3842 | D8: 1 | E8: 0 | F8: 1 | G8: AACOM-CUST-PZ-CLSFI-DSTCD | H8: O | I8: =VLOOKUP(G8,미제공항목!$B$3:$B$43,1,FALSE) -> #N/A
A9: 세부고객유형분류구분코드 | B9: X | C9: 3843 | D9: 2 | E9: 0 | F9: 11 | G9: AACOM-DTALS-CPC-DSTCD | H9: O | I9: =VLOOKUP(G9,미제공항목!$B$3:$B$43,1,FALSE) -> #N/A
A10: 과세구분코드 | B10: X | C10: 3845 | D10: 1 | E10: 0 | F10: 1 | G10: AACOM-TX-DSTCD | H10: O | I10: =VLOOKUP(G10,미제공항목!$B$3:$B$43,1,FALSE) -> #N/A | J10: XDAAE174-O-TX-DSTCD
A11: 거래자구분코드 | B11: X | C11: 3846 | D11: 2 | E11: 0 | F11: 01 | G11: AACOM-TRANR-DSTCD | H11: O | I11: =VLOOKUP(G11,미제공항목!$B$3:$B$43,1,FALSE) -> #N/A
A12: 국적ISO국가코드 | B12: X | C12: 3848 | D12: 2 | E12: 0 | F12: KR | G12: AACOM-NATLTY-ISO-NATNL-CD | H12: O | I12: =VLOOKUP(G12,미제공항목!$B$3:$B$43,1,FALSE) -> #N/A | J12: XDAAE174-O-NATLTY-ISO-NATNL-CD
A13: 거주소재지ISO국가코드 | B13: X | C13: 3850 | D13: 2 | E13: 0 | F13: KR | G13: AACOM-RESI-L-ISO-NATNL-CD | H13: O | I13: =VLOOKUP(G13,미제공항목!$B$3:$B$43,1,FALSE) -> #N/A | J13: XDAAE174-O-RESI-L-ISO-NATNL-CD
A14: 비거주자여부 | B14: X | C14: 3852 | D14: 1 | E14: 0 | F14: 0 | G14: AACOM-NORESI-YN | H14: O | I14: =VLOOKUP(G14,미제공항목!$B$3:$B$43,1,FALSE) -> #N/A | J14: XDAAE174-O-NORESI-YN
A15: 잠재고객여부 | B15: X | C15: 3853 | D15: 1 | E15: 0 | F15: 0 | G15: AACOM-POTEN-CUST-YN | H15: O | I15: =VLOOKUP(G15,미제공항목!$B$3:$B$43,1,FALSE) -> #N/A
A16: 할인고객구분코드 | B16: X | C16: 3854 | D16: 1 | E16: 0 | F16: 1 | G16: AACOM-DSCNT-CUST-DSTCD | H16: O | I16: =VLOOKUP(G16,미제공항목!$B$3:$B$43,1,FALSE) -> #N/A | J16: XDAAE174-O-DSCNT-CUST-DSTCD
A17: 주체별분류코드 | B17: X | C17: 3855 | D17: 5 | E17: 0 | F17: 52201 | G17: AACOM-MBDY-PER-CLSFI-CD | H17: O | I17: =VLOOKUP(G17,미제공항목!$B$3:$B$43,1,FALSE) -> #N/A | J17: XDAAE174-O-MBDY-P-CLSFI-DSTCD
A18: 주체별세부구분코드 | B18: X | C18: 3860 | D18: 2 | E18: 0 | F18: 00 | G18: AACOM-MBDY-P-DTALS-DSTCD | H18: O | I18: =VLOOKUP(G18,미제공항목!$B$3:$B$43,1,FALSE) -> #N/A | J18: XDAAE174-O-MBDY-P-DTALS-DSTCD
A19: 고객상태구분코드 | B19: X | C19: 3862 | D19: 1 | E19: 0 | F19: 1 | G19: AACOM-CUST-STUS-DSTCD | H19: O | I19: =VLOOKUP(G19,미제공항목!$B$3:$B$43,1,FALSE) -> #N/A
A20: 최초등록년월일 | B20: X | C20: 3863 | D20: 8 | E20: 0 | F20: 19970319 | G20: AACOM-FRST-REGI-YMD | H20: O | I20: =VLOOKUP(G20,미제공항목!$B$3:$B$43,1,FALSE) -> #N/A | J20: LOGIC은 있지만 174 모듈의 응답
A21: 최초등록부점코드 | B21: X | C21: 3871 | D21: 4 | E21: 0 | F21: 8020 | G21: AACOM-FRST-REGI-BRNCD | H21: O | I21: =VLOOKUP(G21,미제공항목!$B$3:$B$43,1,FALSE) -> #N/A | J21: LOGIC은 있지만 174 모듈의 응답
A22: 최고등급구분코드 | B22: X | C22: 3875 | D22: 1 | E22: 0 | F22: 1 | G22: AACOM-HGST-CUST-DSTCD | H22: O | I22: =VLOOKUP(G22,미제공항목!$B$3:$B$43,1,FALSE) -> #N/A
A23: 실질등급구분코드 | B23: X | C23: 3876 | D23: 1 | E23: 0 | F23: 5 | G23: AACOM-SELF-AZ-GRD-DSTCD | H23: O | I23: =VLOOKUP(G23,미제공항목!$B$3:$B$43,1,FALSE) -> #N/A | J23: XDAAE174-O-SELF-AZ-GRD-DSTCD
A24: 폼ID | B24: X | C24: 3877 | D24: 11 | E24: 0 | F24: KAA04962000 | G24: AACOM-FM-ID | I24: =VLOOKUP(G24,미제공항목!$B$3:$B$43,1,FALSE) -> AACOM-FM-ID
A25: 카드등급구분코드1 | B25: X | C25: 3888 | D25: 3 | E25: 0 | G25: AACOM-CARD-GRD-DSTCD1 | H25: O | I25: =VLOOKUP(G25,미제공항목!$B$3:$B$43,1,FALSE) -> AACOM-CARD-GRD-DSTCD1 | J25: AACOM X > 0044 에서 다른영역으로?
A26: 카드등급구분코드2 | B26: X | C26: 3891 | D26: 3 | E26: 0 | G26: AACOM-CARD-GRD-DSTCD2 | H26: O | I26: =VLOOKUP(G26,미제공항목!$B$3:$B$43,1,FALSE) -> AACOM-CARD-GRD-DSTCD2 | J26: ?
A27: 카드등급구분코드3 | B27: X | C27: 3894 | D27: 3 | E27: 0 | G27: AACOM-CARD-GRD-DSTCD3 | H27: O | I27: =VLOOKUP(G27,미제공항목!$B$3:$B$43,1,FALSE) -> AACOM-CARD-GRD-DSTCD3 | J27: ?
A28: 금지정보구분코드01 | B28: X | C28: 3897 | D28: 3 | E28: 0 | G28: AACOM-EMBG-I-DSTIC-CD01 | I28: =VLOOKUP(G28,미제공항목!$B$3:$B$43,1,FALSE) -> AACOM-EMBG-I-DSTIC-CD01
A29: 금지정보구분코드02 | B29: X | C29: 3900 | D29: 3 | E29: 0 | G29: AACOM-EMBG-I-DSTIC-CD02 | I29: =VLOOKUP(G29,미제공항목!$B$3:$B$43,1,FALSE) -> AACOM-EMBG-I-DSTIC-CD02
A30: 금지정보구분코드03 | B30: X | C30: 3903 | D30: 3 | E30: 0 | G30: AACOM-EMBG-I-DSTIC-CD03 | I30: =VLOOKUP(G30,미제공항목!$B$3:$B$43,1,FALSE) -> AACOM-EMBG-I-DSTIC-CD03
A31: 금지정보구분코드04 | B31: X | C31: 3906 | D31: 3 | E31: 0 | G31: AACOM-EMBG-I-DSTIC-CD04 | I31: =VLOOKUP(G31,미제공항목!$B$3:$B$43,1,FALSE) -> AACOM-EMBG-I-DSTIC-CD04
A32: 금지정보구분코드05 | B32: X | C32: 3909 | D32: 3 | E32: 0 | G32: AACOM-EMBG-I-DSTIC-CD05 | I32: =VLOOKUP(G32,미제공항목!$B$3:$B$43,1,FALSE) -> AACOM-EMBG-I-DSTIC-CD05
A33: 금지정보구분코드06 | B33: X | C33: 3912 | D33: 3 | E33: 0 | G33: AACOM-EMBG-I-DSTIC-CD06 | I33: =VLOOKUP(G33,미제공항목!$B$3:$B$43,1,FALSE) -> AACOM-EMBG-I-DSTIC-CD06
A34: 금지정보구분코드07 | B34: X | C34: 3915 | D34: 3 | E34: 0 | G34: AACOM-EMBG-I-DSTIC-CD07 | I34: =VLOOKUP(G34,미제공항목!$B$3:$B$43,1,FALSE) -> AACOM-EMBG-I-DSTIC-CD07
A35: 금지정보구분코드08 | B35: X | C35: 3918 | D35: 3 | E35: 0 | G35: AACOM-EMBG-I-DSTIC-CD08 | I35: =VLOOKUP(G35,미제공항목!$B$3:$B$43,1,FALSE) -> AACOM-EMBG-I-DSTIC-CD08
A36: 금지정보구분코드09 | B36: X | C36: 3921 | D36: 3 | E36: 0 | G36: AACOM-EMBG-I-DSTIC-CD | I36: =VLOOKUP(G36,미제공항목!$B$3:$B$43,1,FALSE) -> AACOM-EMBG-I-DSTIC-CD
A37: 금지정보구분코드10 | B37: X | C37: 3924 | D37: 3 | E37: 0 | G37: AACOM-EMBG-I-DSTIC-CD10 | I37: =VLOOKUP(G37,미제공항목!$B$3:$B$43,1,FALSE) -> AACOM-EMBG-I-DSTIC-CD10
A38: 정상부가메시지코드 | B38: X | C38: 3927 | D38: 8 | E38: 0 | G38: AACOM-ADED-MSG-CD | I38: =VLOOKUP(G38,미제공항목!$B$3:$B$43,1,FALSE) -> AACOM-ADED-MSG-CD
A39: 사업자번호 | B39: X | C39: 3935 | D39: 10 | E39: 0 | G39: AACOM-BZNO | H39: O | I39: =VLOOKUP(G39,미제공항목!$B$3:$B$43,1,FALSE) -> #N/A | J39: 특정조건에 의해 BPBS 테이블 탐색
A40: 알리미표시여부 | B40: X | C40: 3945 | D40: 1 | E40: 0 | F40: 1 | G40: AACOM-ALMI-REPSNT-YN | I40: =VLOOKUP(G40,미제공항목!$B$3:$B$43,1,FALSE) -> AACOM-ALMI-REPSNT-YN
...

Sheet 고객정보
A1: 한글필드명 | B1: 필드명 | C1: TOBE | I1: IAACOMM
A2: 고객식별자 | B2: AACOM-CUST-IDNFR | C2: FUCustBaseInfoMgt.getCustBascInfo() | D2: 기본정보 | I2: XDAAE174-O-CUST-IDNFR
A3: 고객관리번호 | B3: AACOM-CUST-MGT-NO | C3: FUCustBaseInfoMgt.getCustBascInfo() | D3: 기본정보 | I3: XDAAE174-O-CUST-MGT-NO
A4: 고객고유번호 | B4: AACOM-CUNIQNO | C4: FUCustBaseInfoMgt.getCustBascInfo() | D4: 기본정보 | I4: 메모참고 (IF/ELSE)
A5: 고객고유번호구분코드 | B5: AACOM-CUNIQNO-DSTCD | C5: FUCustBaseInfoMgt.getCustBascInfo() | D5: 기본정보 | I5: 상동
A6: 고객명1 | B6: AACOM-DTALS-CUSTNM1 | C6: FUCustBaseInfoMgt.getCustBascInfo() | D6: 기본정보 | I6: XDAAE174-O-CUSTNM1
A7: 고객명2 | B7: AACOM-DTALS-CUSTNM2 | C7: FUCustBaseInfoMgt.getCustBascInfo() | D7: 기본정보 | I7: XDAAE174-O-CUSTNM2
A8: 고객유형분류구분코드 | B8: AACOM-CUST-PZ-CLSFI-DSTCD | C8: FUCustBaseInfoMgt.getCustBascInfo() | D8: 기본정보 | I8: DAAE174 프로그램에서 CO-STAT-DUPM 오류코드 발생시 (중복고객) 해당사업자번호로 1개이상 조회되었을때, (사업자명 또는 대표개인 추가요함)
A9: 세부고객유형분류구분코드 | B9: AACOM-DTALS-CPC-DSTCD | C9: FUCustBaseInfoMgt.getCustBascInfo() | D9: 기본정보 | I9: XDAAE174-O-DTALS-CPC-DSTCD
A10: 과세구분코드 | B10: AACOM-TX-DSTCD | C10: FUBznoInfoMgt.getPpsnCustDtailInfo() FUBznoInfoMgt.getCoprCustDtailInfo() | D10: 고객유형분규구분에 따른 상세조회 | I10: XDAAE174-O-TX-DSTCD
A11: 거래자구분코드 | B11: AACOM-TRANR-DSTCD | C11: FUCustBaseInfoMgt.getCustBascInfo() | D11: 기본정보 | I11: XDAAE174-O-TRANR-DSTCD
A12: 국적ISO국가코드 | B12: AACOM-NATLTY-ISO-NATNL-CD | C12: FUBznoInfoMgt.getPpsnCustDtailInfo() FUBznoInfoMgt.getCoprCustDtailInfo() | D12: 고객유형분규구분에 따른 상세조회 | I12: XDAAE174-O-NATLTY-ISO-NATNL-CD
A13: 거주소재지ISO국가코드 | B13: AACOM-RESI-L-ISO-NATNL-CD | C13: FUBznoInfoMgt.getPpsnCustDtailInfo() FUBznoInfoMgt.getCoprCustDtailInfo() | D13: 고객유형분규구분에 따른 상세조회 | I13: XDAAE174-O-RESI-L-ISO-NATNL-CD
... A15: 잠재고객여부 | B15: AACOM-POTEN-CUST-YN | C15: FUCustBaseInfoMgt.getCustBascInfo() | D15: 기본정보 | I15: XDAAE174-O-POTEN-CUST-YN
A16: 할인고객구분코드 | B16: AACOM-DSCNT-CUST-DSTCD | C16: N/A | I16: XDAAE174-O-DSCNT-CUST-DSTCD
A17: 주체별분류코드 | B17: AACOM-MBDY-PER-CLSFI-CD | C17: FUBznoInfoMgt.getPpsnCustDtailInfo() FUBznoInfoMgt.getCoprCustDtailInfo() | D17: 고객유형분규구분에 따른 상세조회 | I17: XDAAE174-O-MBDY-P-CLSFI-DSTCD
A18: 주체별세부구분코드 | B18: AACOM-MBDY-P-DTALS-DSTCD | C18: FUBznoInfoMgt.getPpsnCustDtailInfo() FUBznoInfoMgt.getCoprCustDtailInfo() | D18: 고객유형분규구분에 따른 상세조회 | I18: XDAAE174-O-MBDY-P-DTALS-DSTCD
A19: 고객상태구분코드 | B19: AACOM-CUST-STUS-DSTCD | C19: FUCustBaseInfoMgt.getCustBascInfo() | D19: 기본정보 | I19: XDAAE174-O-CUST-STUS-DSTCD
A20: 최초등록년월일 | B20: AACOM-FRST-REGI-YMD | C20: FUBznoInfoMgt.getPpsnCustDtailInfo() FUBznoInfoMgt.getCoprCustDtailInfo() | D20: 고객유형분규구분에 따른 상세조회 | E20: 메모내용에 따라 주고있지는 않음 | I20: 메모참고 (IF/ELSE)
A21: 최초등록부점코드 | B21: AACOM-FRST-REGI-BRNCD | C21: FUBznoInfoMgt.getPpsnCustDtailInfo() FUBznoInfoMgt.getCoprCustDtailInfo() | D21: 고객유형분규구분에 따른 상세조회 | E21: 메모내용에 따라 주고있지는 않음 | I21: 메모참고 (IF/ELSE)
A22: 최고등급구분코드 | B22: AACOM-HGST-CUST-DSTCD | C22: N/A | I22: XDAAE174-O-HGST-CUST-DSTCD
A23: 실질등급구분코드 | B23: AACOM-SELF-AZ-GRD-DSTCD | C23: N/A | I23: XDAAE174-O-SELF-AZ-GRD-DSTCD
A24: 폼ID | B24: AACOM-FM-ID | I24: 상수영역 셋팅
A25: 카드등급구분코드1 | B25: AACOM-CARD-GRD-DSTCD1 | I25: X
A26: 카드등급구분코드2 | B26: AACOM-CARD-GRD-DSTCD2 | I26: X
A27: 카드등급구분코드3 | B27: AACOM-CARD-GRD-DSTCD3 | I27: X
A28: 금지정보구분코드01 | B28: AACOM-EMBG-I-DSTIC-CD01 | I28: X
A29: 금지정보구분코드02 | B29: AACOM-EMBG-I-DSTIC-CD02 | I29: X
A30: 금지정보구분코드03 | B30: AACOM-EMBG-I-DSTIC-CD03 | I30: X
A31: 금지정보구분코드04 | B31: AACOM-EMBG-I-DSTIC-CD04 | I31: X
A32: 금지정보구분코드05 | B32: AACOM-EMBG-I-DSTIC-CD05 | I32: X
A33: 금지정보구분코드06 | B33: AACOM-EMBG-I-DSTIC-CD06 | I33: X
A34: 금지정보구분코드07 | B34: AACOM-EMBG-I-DSTIC-CD07 | I34: X
A35: 금지정보구분코드08 | B35: AACOM-EMBG-I-DSTIC-CD08 | I35: X
A36: 금지정보구분코드09 | B36: AACOM-EMBG-I-DSTIC-CD | I36: X
A37: 금지정보구분코드10 | B37: AACOM-EMBG-I-DSTIC-CD10 | C37: N/A | I37: XDAAE174-O-CUST-STUS-DSTCD 의 값에 의해 CASE / WHEN 구문
A38: 정상부가메시지코드 | B38: AACOM-ADED-MSG-CD | I38: X
A39: 사업자번호 | B39: AACOM-BZNO | C39: FUBznoInfoMgt.getPpsnCustDtailInfo() FUBznoInfoMgt.getCoprCustDtailInfo() | D39: 고객유형분규구분에 따른 상세조회 개인사업자번호 / 법인사업자등록번호 | E39: 메모내용에 따라 주고있지는 않음 | I39: 메모참고 (IF/ELSE)
A40: 알리미표시여부 | B40: AACOM-ALMI-REPSNT-YN | C40: N/A | I40: 메모참고 (IF/ELSE)
A41: 기업규모구분코드 | B41: AACOM-CORP-SCAL-DSTCD | C41: FUBznoInfoMgt.getPpsnCustDtailInfo() FUBznoInfoMgt.getCoprCustDtailInfo() | D41: 고객유형분규구분에 따른 상세조회 | I41: DAAK441 법인조회 DC프로그램 호출
...
